<?xml version="1.0"?>
<!-- This URDF was automatically created by SolidWorks to URDF Exporter! Originally created by Stephen Brawner (brawner@gmail.com) 
     Commit Version: 1.6.0-4-g7f85cfe  Build Version: 1.6.7995.38578
     For more information, please see http://wiki.ros.org/sw_urdf_exporter -->
<robot
  name="carone" xmlns:xacro="http://ros.org/wiki/xacro">

  <!-- <link name="dummy_link"></link> -->

  <link                       
    name="base_link">
    <inertial>
      <origin
        xyz="-0.43006 -0.028684 -0.26994"
        rpy="0 0 0" />
      <mass
        value="0.29429" />
      <inertia
        ixx="0.0025713"
        ixy="-5.709E-18"
        ixz="7.5873E-19"
        iyy="0.013953"
        iyz="8.914E-20"
        izz="0.016514" />
    </inertial>
    <visual>
      <origin
        xyz="0 0 0"
        rpy="0 0 " />
      <geometry>
        <mesh
          filename="package://carone/meshes/base_link.STL" />
      </geometry>
      <material
        name="">
        <color
          rgba="0.79216 0.81961 0.93333 1" />
      </material>
    </visual>
    <collision>
      <origin
        xyz="0 0 0"
        rpy="0 0 0" />
      <geometry>
        <mesh
          filename="package://carone/meshes/base_link.STL" />
      </geometry>
    </collision>
  </link>

  <!-- <joint name="dummy_joint" type="fixed">
      <origin rpy="0 0 0" xyz="0 0 0" />
      <parent link="dummy_link"/>
      <child link="base_link"/>
  </joint> -->

  <link
    name="br_rim">
    <inertial>
      <origin
        xyz="0.035554 1.1292E-06 -1.9665E-08"
        rpy="0 0 0" />
      <mass
        value="0.52126" />
      <inertia
        ixx="0.0016561"
        ixy="-5.114E-08"
        ixz="1.635E-10"
        iyy="0.0010043"
        iyz="1.572E-11"
        izz="0.0010043" />
    </inertial>
    <visual>
      <origin
        xyz="0 0 0"
        rpy="0 0 0" />
      <geometry>
        <mesh
          filename="package://carone/meshes/br_rim.STL" />
      </geometry>
      <material
        name="">
        <color
          rgba="0.89804 0.91765 0.92941 1" />
      </material>
    </visual>
    <collision>
      <origin
        xyz="0 0 0"
        rpy="0 0 0" />
      <geometry>
        <mesh
          filename="package://carone/meshes/br_rim.STL" />
      </geometry>
    </collision>
  </link>

  <joint
    name="BR"
    type="continuous">
    <origin
      xyz="-0.19014 0.14364 -0.26994"
      rpy="-0.12666 0 1.5708" />
    <parent
      link="base_link" />
    <child
      link="br_rim" />
    <axis
      xyz="1 0 0" />
    <limit
      effort="50"
      velocity="100" />
  </joint>
  <link
    name="br_tyre">
    <inertial>
      <origin
        xyz="3.6417E-11 3.896E-11 -0.00016637"
        rpy="0 0 0" />
      <mass
        value="0.20778" />
      <inertia
        ixx="0.001018"
        ixy="-4.0387E-17"
        ixz="-2.5676E-15"
        iyy="0.001018"
        iyz="-3.5579E-14"
        izz="0.0017529" />
    </inertial>
    <visual>
      <origin
        xyz="0 0 0"
        rpy="0 0 0" />
      <geometry>
        <mesh
          filename="package://carone/meshes/br_tyre.STL" />
      </geometry>
      <material
        name="">
        <color
          rgba="0.79216 0.81961 0.93333 1" />
      </material>
    </visual>
    <collision>
      <origin
        xyz="0 0 0"
        rpy="0 0 0" />
      <geometry>
        <mesh
          filename="package://carone/meshes/br_tyre.STL" />
      </geometry>
    </collision>
  </link>

  <joint
    name="BR_tyre"
    type="fixed">
    <origin
      xyz="0.031367 0 0"
      rpy="1.5708 -0.50843 -1.5708" />
    <parent
      link="br_rim" />
    <child
      link="br_tyre" />
    <axis
      xyz="0 0 0" />
  </joint>

  <link
    name="bl_rim">
    <inertial>
      <origin
        xyz="0.0355543878993591 1.12922893685807E-06 -1.96665647100858E-08"
        rpy="0 0 0" />
      <mass
        value="0.5212595765443" />
      <inertia
        ixx="0.00165605036423408"
        ixy="-5.11397415072429E-08"
        ixz="1.63506388221507E-10"
        iyy="0.00100431964929698"
        iyz="1.57238722096973E-11"
        izz="0.00100426065146841" />
    </inertial>
    <visual>
      <origin
        xyz="0 0 0"
        rpy="0 0 0" />
      <geometry>
        <mesh
          filename="package://carone/meshes/bl_rim.STL" />
      </geometry>
      <material
        name="">
        <color
          rgba="0.898039215686275 0.917647058823529 0.929411764705882 1" />
      </material>
    </visual>
    <collision>
      <origin
        xyz="0 0 0"
        rpy="0 0 0" />
      <geometry>
        <mesh
          filename="package://carone/meshes/bl_rim.STL" />
      </geometry>
    </collision>
  </link>
  <joint
    name="BL"
    type="continuous">
    <origin
      xyz="-0.19014 -0.20101 -0.26994"
      rpy="2.7543 0 -1.5708" />
    <parent
      link="base_link" />
    <child
      link="bl_rim" />
    <axis
      xyz="1 0 0" />
    <limit
      effort="50"
      velocity="100" />
  </joint>
  <link
    name="bl_tyre">
    <inertial>
      <origin
        xyz="-2.84616774592905E-12 -5.32447974599393E-11 -0.000166372092178013"
        rpy="0 0 0" />
      <mass
        value="0.207777502808362" />
      <inertia
        ixx="0.00101800536237172"
        ixy="-2.22884861608708E-16"
        ixz="-2.09071463417761E-14"
        iyy="0.00101800536237172"
        iyz="2.8890050378608E-14"
        izz="0.00175294336659733" />
    </inertial>
    <visual>
      <origin
        xyz="0 0 0"
        rpy="0 0 0" />
      <geometry>
        <mesh
          filename="package://carone/meshes/bl_tyre.STL" />
      </geometry>
      <material
        name="">
        <color
          rgba="0.792156862745098 0.819607843137255 0.933333333333333 1" />
      </material>
    </visual>
    <collision>
      <origin
        xyz="0 0 0"
        rpy="0 0 0" />
      <geometry>
        <mesh
          filename="package://carone/meshes/bl_tyre.STL" />
      </geometry>
    </collision>
  </link>
  <joint
    name="BL_tyre"
    type="fixed">
    <origin
      xyz="0.031367 0 0"
      rpy="1.5708 0.45048 -1.5708" />
    <parent
      link="bl_rim" />
    <child
      link="bl_tyre" />
    <axis
      xyz="0 0 0" />
  </joint>


  <link
    name="body_link">
    <inertial>
      <origin
        xyz="0.204577583766421 0.199814344019782 -0.25374023596054"
        rpy="0 0 0" />
      <mass
        value="3.1662503482962" />
      <!-- <inertia
        ixx="2.6370812954841"
        ixy="0.00510956884646856"
        ixz="-0.00285596742227791"
        iyy="2.9547878788717"
        iyz="0.087288084116685"
        izz="1.03489975512672" /> -->
      <inertia
        ixx="0.0"
        ixy="0.0"
        ixz="0.0"
        iyy="0.0"
        iyz="0.0"
        izz="0.0" />
    </inertial>
    <visual>
      <origin
        xyz="0 0 0"
        rpy="0 0 0" />
      <geometry>
        <mesh
          filename="package://carone/meshes/body_link.STL" />
      </geometry>
      <material
        name="">
        <color
          rgba="0.792156862745098 0.819607843137255 0.933333333333333 1" />
      </material>
    </visual>
    <collision>
      <origin
        xyz="0 0 0"
        rpy="0 0 0" />
      <geometry>
        <mesh
          filename="package://carone/meshes/body_link.STL" />
      </geometry>
    </collision>
  </link>
  <joint
    name="body_joint"
    type="fixed">
    <origin
      xyz="-0.67676 0.17439 -0.27592"
      rpy="1.5708 0 -1.5708" />
    <parent
      link="base_link" />
    <child
      link="body_link" />
    <axis
      xyz="0 0 0" />
  </joint>



  <link
    name="lidar_link">
    <inertial>
      <origin
        xyz="0 0 0.03175"
        rpy="0 0 0" />
      <mass
        value="0.128703699690764" />
      <inertia
        ixx="6.4005744146297E-05"
        ixy="1.6940658945086E-21"
        ixz="3.58196101728781E-21"
        iyy="6.4005744146297E-05"
        iyz="2.78473637591801E-22"
        izz="4.15172394462466E-05" />
    </inertial>
    <visual>
      <origin
        xyz="0 0 -0.04"
        rpy="0 0 0" />
      <geometry>
        <mesh
          filename="package://carone/meshes/lidar_link.STL" />
      </geometry>
      <material
        name="">
        <color
          rgba="0.792156862745098 0.819607843137255 0.933333333333333 1" />
      </material>
    </visual>
    <collision>
      <origin
        xyz="0 0 -0.04"
        rpy="0 0 0" />
      <geometry>
        <mesh
          filename="package://carone/meshes/lidar_link.STL" />
      </geometry>
    </collision>
  </link>
  <joint
    name="lidar_joint"
    type="fixed">
    <origin
      xyz="0.20311 0.41576 -0.30198"
      rpy="1.5708 0.1562 3.1416" />
    <parent
      link="body_link" />
    <child
      link="lidar_link" />
    <axis
      xyz="0 0 0" />
  </joint>
  <link
    name="frsteer">
    <inertial>
      <origin
        xyz="4.23928203652224E-09 0.0230860363341096 -0.00749300067566538"
        rpy="0 0 0" />
      <mass
        value="0.00684767490112769" />
      <inertia
        ixx="1.12403678391785E-06"
        ixy="1.81305393167647E-13"
        ixz="-1.11407408384264E-13"
        iyy="1.8161497531784E-07"
        iyz="-2.19876902369232E-13"
        izz="1.13256633136179E-06" />
    </inertial>
    <visual>
      <origin
        xyz="0 0 0"
        rpy="0 0 0" />
      <geometry>
        <mesh
          filename="package://carone/meshes/frsteer.STL" />
      </geometry>
      <material
        name="">
        <color
          rgba="0.792156862745098 0.819607843137255 0.933333333333333 1" />
      </material>
    </visual>
    <collision>
      <origin
        xyz="0 0 0"
        rpy="0 0 0" />
      <geometry>
        <mesh
          filename="package://carone/meshes/frsteer.STL" />
      </geometry>
    </collision>
  </link>
  <joint
    name="Rsteer"
    type="revolute">
    <origin
      xyz="-0.69814 0.15775 -0.26244"
      rpy="0 0 -0.0028624" />
    <parent
      link="base_link" />
    <child
      link="frsteer" />
    <axis
      xyz="0 0 1" />
    <limit
      lower="-0.524"
      upper="0.524"
      effort="50"
      velocity="100" />
  </joint>
  <link
    name="fr_rim">
    <inertial>
      <origin
        xyz="0.0224562515014283 1.12922776346336E-06 -1.966536522513E-08"
        rpy="0 0 0" />
      <mass
        value="0.521259576580297" />
      <inertia
        ixx="0.00165605036422283"
        ixy="-5.11397356689807E-08"
        ixz="1.63501214944509E-10"
        iyy="0.00100431964927735"
        iyz="1.57202691619326E-11"
        izz="0.00100426065148434" />
    </inertial>
    <visual>
      <origin
        xyz="0 0 0"
        rpy="0 0 0" />
      <geometry>
        <mesh
          filename="package://carone/meshes/fr_rim.STL" />
      </geometry>
      <material
        name="">
        <color
          rgba="0.898039215686275 0.917647058823529 0.929411764705882 1" />
      </material>
    </visual>
    <collision>
      <origin
        xyz="0 0 0"
        rpy="0 0 0" />
      <geometry>
        <mesh
          filename="package://carone/meshes/fr_rim.STL" />
      </geometry>
    </collision>
  </link>
  <joint
    name="FR"
    type="continuous">
    <origin
      xyz="0 0 -0.007493"
      rpy="-2.3163 0 1.5708" />
    <parent
      link="frsteer" />
    <child
      link="fr_rim" />
    <axis
      xyz="1 0 0" />
    <limit
      effort="50"
      velocity="100" />
  </joint>
  <link
    name="fr_tyre">
    <inertial>
      <origin
        xyz="7.58526574884399E-12 -4.32347491141627E-11 -0.000166372092113509"
        rpy="0 0 0" />
      <mass
        value="0.207777502808153" />
      <inertia
        ixx="0.0010180053623714"
        ixy="-1.36799209113359E-16"
        ixz="-2.21259078385991E-14"
        iyy="0.00101800536237126"
        iyz="1.929716484954E-14"
        izz="0.00175294336659694" />
    </inertial>
    <visual>
      <origin
        xyz="0 0 0"
        rpy="0 0 0" />
      <geometry>
        <mesh
          filename="package://carone/meshes/fr_tyre.STL" />
      </geometry>
      <material
        name="">
        <color
          rgba="0.792156862745098 0.819607843137255 0.933333333333333 1" />
      </material>
    </visual>
    <collision>
      <origin
        xyz="0 0 0"
        rpy="0 0 0" />
      <geometry>
        <mesh
          filename="package://carone/meshes/fr_tyre.STL" />
      </geometry>
    </collision>
  </link>
  <joint
    name="FR_tyre"
    type="fixed">
    <origin
      xyz="0.018269 0 0"
      rpy="1.5708 -0.53496 -1.5708" />
    <parent
      link="fr_rim" />
    <child
      link="fr_tyre" />
    <axis
      xyz="0 0 0" />
  </joint>
  <link
    name="flsteer">
    <inertial>
      <origin
        xyz="-9.07655284265729E-10 0.023053675241899 -0.00762000007042807"
        rpy="0 0 0" />
      <mass
        value="0.00685729546814415" />
      <inertia
        ixx="1.12969971208241E-06"
        ixy="-4.27767741332011E-13"
        ixz="-1.12514721296136E-13"
        iyy="1.82174453610606E-07"
        iyz="-4.12384154391679E-15"
        izz="1.13771501163283E-06" />
    </inertial>
    <visual>
      <origin
        xyz="0 0 0"
        rpy="0 0 0" />
      <geometry>
        <mesh
          filename="package://carone/meshes/flsteer.STL" />
      </geometry>
      <material
        name="">
        <color
          rgba="0.792156862745098 0.819607843137255 0.933333333333333 1" />
      </material>
    </visual>
    <collision>
      <origin
        xyz="0 0 0"
        rpy="0 0 0" />
      <geometry>
        <mesh
          filename="package://carone/meshes/flsteer.STL" />
      </geometry>
    </collision>
  </link>
  <joint
    name="Lsteer"
    type="revolute">
    <origin
      xyz="-0.69814 -0.21512 -0.26232"
      rpy="0 0 3.1196" />
    <parent
      link="base_link" />
    <child
      link="flsteer" />
    <axis
      xyz="0 0 1" />
    <limit
      lower="-0.524"
      upper="0.524"
      effort="50"
      velocity="100" />
  </joint>
  <link
    name="fl_rim">
    <inertial>
      <origin
        xyz="0.0224562515014287 1.12922776335234E-06 -1.96653650030854E-08"
        rpy="0 0 0" />
      <mass
        value="0.521259576580302" />
      <inertia
        ixx="0.00165605036422283"
        ixy="-5.11397356677187E-08"
        ixz="1.6350121242483E-10"
        iyy="0.00100431964927736"
        iyz="1.57202685338577E-11"
        izz="0.00100426065148434" />
    </inertial>
    <visual>
      <origin
        xyz="0 0 0"
        rpy="0 0 0" />
      <geometry>
        <mesh
          filename="package://carone/meshes/fl_rim.STL" />
      </geometry>
      <material
        name="">
        <color
          rgba="0.898039215686275 0.917647058823529 0.929411764705882 1" />
      </material>
    </visual>
    <collision>
      <origin
        xyz="0 0 0"
        rpy="0 0 0" />
      <geometry>
        <mesh
          filename="package://carone/meshes/fl_rim.STL" />
      </geometry>
    </collision>
  </link>
  <joint
    name="FL"
    type="continuous">
    <origin
      xyz="0 0 -0.00762"
      rpy="-1.564 0 1.5708" />
    <parent
      link="flsteer" />
    <child
      link="fl_rim" />
    <axis
      xyz="1 0 0" />
    <limit
      effort="50"
      velocity="100" />
  </joint>
  <link
    name="fl_tyre">
    <inertial>
      <origin
        xyz="-1.5287437982181E-11 -1.12618803171927E-11 -0.000166372092002598"
        rpy="0 0 0" />
      <mass
        value="0.207777502807794" />
      <inertia
        ixx="0.0010180053623706"
        ixy="1.11130722679764E-17"
        ixz="3.21282949811885E-15"
        iyy="0.00101800536237065"
        iyz="1.22835434877693E-14"
        izz="0.00175294336659621" />
    </inertial>
    <visual>
      <origin
        xyz="0 0 0"
        rpy="0 0 0" />
      <geometry>
        <mesh
          filename="package://carone/meshes/fl_tyre.STL" />
      </geometry>
      <material
        name="">
        <color
          rgba="0.792156862745098 0.819607843137255 0.933333333333333 1" />
      </material>
    </visual>
    <collision>
      <origin
        xyz="0 0 0"
        rpy="0 0 0" />
      <geometry>
        <mesh
          filename="package://carone/meshes/fl_tyre.STL" />
      </geometry>
    </collision>
  </link>
  <joint
    name="FL_tyre"
    type="fixed">
    <origin
      xyz="0.018502 0 0"
      rpy="-1.5708 -0.75862 -1.5708" />
    <parent
      link="fl_rim" />
    <child
      link="fl_tyre" />
    <axis
      xyz="0 0 0" />
  </joint>
 
 #######################################################################################################################


<ros2_control name="GazeboSystem" type="system">
  <hardware>
  <plugin>gazebo_ros2_control/GazeboSystem</plugin>
  </hardware> 

# ------------------------------------------------------- Velocity controllers 

  <joint name="BR">
    <command_interface name="velocity">
      <param name="min">-1000.0</param>
      <param name="max">1000.0</param>
    </command_interface>
    <state_interface name="position"/>
    <state_interface name="velocity"/>
  </joint>

  <joint name="BL">
    <command_interface name="velocity">
      <param name="min">-1000.0</param>
      <param name="max">1000.0</param>
    </command_interface>
    <state_interface name="position"/>
    <state_interface name="velocity"/>
  </joint>

  <!-- <joint name="FL">
    <command_interface name="velocity">
      <param name="min">-1000.0</param>
      <param name="max">1000.0</param>
    </command_interface>
    <state_interface name="position"/>
    <state_interface name="velocity"/>
  </joint>


  <joint name="FR">
    <command_interface name="velocity">
      <param name="min">-1000.0</param>
      <param name="max">1000.0</param>
    </command_interface>
    <state_interface name="position"/>
    <state_interface name="velocity"/>
  </joint> -->

# ------------------------------------------------------- Position controllers

  <joint name="Lsteer">
    <command_interface name="position">
    <param name="min">-3.14</param>
    <param name="max">3.14</param>
    </command_interface>
    <state_interface name="position"/>
    <state_interface name="velocity"/>
  </joint>


  <joint name="Rsteer">
    <command_interface name="position">
    <param name="min">-3.14</param>
    <param name="max">3.14</param>
    </command_interface>
    <state_interface name="position"/>
    <state_interface name="velocity"/>
  </joint>
</ros2_control>

<gazebo>
<plugin filename="libgazebo_ros2_control.so" name="gazebo_ros2_control">
<parameters>$(find carone)/config/control.yaml</parameters>
</plugin>
</gazebo>

# ------------------------------------------------------LIDAR link and properties

<gazebo reference="lidar_link">
  <sensor name="lidar" type="ray">
    <!-- <pose>0.0 0.0 0.03 0 0 0</pose> -->
    <always_on>true</always_on>
    <visualize>true</visualize>
    <update_rate>10</update_rate>
    <ray>
      <scan>
        <horizontal>
          <samples>7</samples>
          <resolution>1.00000</resolution>
          <min_angle>1.00</min_angle>
          <max_angle>2.34</max_angle>
        </horizontal>
      </scan>
      <range>
        <min>0.10000</min>
        <max>5</max>
        <resolution>0.015000</resolution>
      </range>
      <noise>
        <type>gaussian</type>
        <mean>0.0</mean>
        <stddev>0.01</stddev>
      </noise>
    </ray>
    <plugin name="scan" filename="libgazebo_ros_ray_sensor.so">
      <ros>
        <remapping>~/out:=scan</remapping>
      </ros>
      <output_type>sensor_msgs/LaserScan</output_type>
      <frame_name>lidar_link</frame_name>
    </plugin>
  </sensor>
  </gazebo>

# --------------------------------------------IMU link, joint and configuration

<link name="imu_link">
    <visual>
       <geometry>
       <cylinder length="0.06" radius="0.02"/>
      </geometry>
    </visual>
  </link>

<joint name="imujoint" type="fixed">
    <origin
      xyz="-0.2 -0.03 -0.05"
      rpy="0 0 0" />    
    <parent
      link="base_link" />
    <child
      link="imu_link" />
</joint>


<gazebo reference="imu_link">
  <gravity>true</gravity>
  <sensor name="imu_sensor" type="imu">
    <always_on>true</always_on>
    <update_rate>100</update_rate>
    <visualize>true</visualize>
    <topic>__default_topic__</topic>
    <plugin filename="libgazebo_ros_imu_sensor.so" name="imu_plugin">
      <topicName>imu</topicName>
      <bodyName>imu_link</bodyName>
      <updateRateHZ>10.0</updateRateHZ>
      <gaussianNoise>0.0</gaussianNoise>
      <xyzOffset>0 0 0</xyzOffset>
      <rpyOffset>0 0 0</rpyOffset>
      <frameName>imu_link</frameName>
      <initialOrientationAsReference>false</initialOrientationAsReference>
    </plugin>
    <pose>0 0 0 0 0 0</pose>
  </sensor>
</gazebo>


# ------------------------------------------------------- Color of the links

<xacro:macro name="body_color">
<visual><material>
<ambient>0.2 0.2 0.2 1</ambient>
<diffuse>0.13 0.13 0 1</diffuse>
<specular>0.1 0.1 0.1 1</specular>
<emissive>0 0 0 0</emissive>
</material></visual>
</xacro:macro>

<gazebo reference="body_link">
    <xacro:body_color />
</gazebo>

<gazebo reference="br_tyre">
    <material>Gazebo/DarkGrey</material>
</gazebo>

<gazebo reference="bl_tyre">
    <material>Gazebo/DarkGrey</material>
</gazebo>

<gazebo reference="fl_tyre">
    <material>Gazebo/DarkGrey</material>
</gazebo>

<gazebo reference="fr_tyre">
    <material>Gazebo/DarkGrey</material>
</gazebo>

</robot>